<?xml version="1.0"?>
<robot xmlns:xacro="http://www.ros.org/wiki/xacro" name="mapper">

<!-- Including plugins and material files -->
<xacro:include filename="$(find structure)/urdf/materials.gazebo"/>
<xacro:include filename="$(find structure)/urdf/plugins.gazebo"/>

<!-- BASE-FOOTPRINT -->
  <!-- base_footprint is a fictitious link(frame) that is on the ground right below base_link origin -->
<link name="base_footprint">
  <inertial>
    <mass value="0.0001" />
    <origin xyz="0 0 0" rpy="0 0 0"/>
    <inertia ixx="0.0001" ixy="0.0" ixz="0.0"
        iyy="0.0001" iyz="0.0" 
        izz="0.0001" />
  </inertial>
  <visual>
      <origin xyz="0 0 0" rpy="0 0 0" />
      <geometry>
          <box size="0.001 0.001 0.001" />
      </geometry>
  </visual>
</link>
<gazebo reference="base_footprint">
  <turnGravityOff>false</turnGravityOff>
</gazebo>
<joint name="base_footprint_joint" type="fixed">
  <origin xyz="0 0 0.3" rpy="0 0 0" />
  <parent link="base_footprint"/>
  <child link="base_link" />
</joint>



<!--  Chassis link -->
    <link name="base_link">
      <inertial>
        <mass value="5"/>
        <origin rpy="0 0 0" xyz="0 0 0"/>
        <inertia ixx="0.166667" ixy="0" ixz="0" iyy="0.166667" iyz="0" izz="0.166667"/>
      </inertial>
        <visual>
            <origin rpy="0  0  0" xyz="0  0  0"/>
            <geometry>
              <box size="1 0.8 0.2"/>
            </geometry>
        </visual>
        <collision name="collision_chassis">
            <origin rpy="0 0 0" xyz="0 0 0"/>
            <geometry>
              <box size="1 0.8 0.2"/>
            </geometry>
        </collision>
    </link>
    

<!-- Caster wheel -->
    <link name="caster_wheel">
      <collision>
        <origin rpy=" 0 0 0" xyz="0 0 0"/>
        <geometry>
          <sphere radius="0.199"/>
        </geometry>
        <surface>
          <friction>
            <ode>
              <mu>0</mu>
              <mu2>0</mu2>
            </ode>
          </friction>
          <contact>
            <ode>
              <min_depth>0.003</min_depth>
            </ode>
          </contact>
        </surface>
      </collision>
      <visual >
        <origin rpy=" 0 0 0" xyz="0 0 0"/>
        <geometry>
          <sphere radius="0.199"/>
        </geometry>
      </visual>
      <inertial>
        <mass value="0.5"/>
        <origin rpy="0 0 0" xyz="0 0 0"/>
        <inertia ixx="0" ixy="0" ixz="0" iyy="0" iyz="0" izz="0"/>
      </inertial>
    </link>
  <!-- Caster joint -->
    <joint name="caster_wheel_joint" type="continuous">
      <axis xyz="0 1 0" rpy="0 0 0" />
      <parent link="base_link"/>
      <child link="caster_wheel"/>
      <origin xyz="0.3 0 -0.1" rpy="0 0 0"/>
    </joint>


    <!-- Wheel links macro -->
    <xacro:macro name="wheels" params="name">
      <link name="${name}_wheel">
        <inertial>
          <mass value="0.2"/>
          <origin rpy="0 0 0" xyz="0 0 0"/>
          <inertia ixx="0.004666666666666667" ixy="0" ixz="0" iyy="0.004666666666666667" iyz="0" izz="0.009"/>
        </inertial>
        <collision>
          <origin rpy="0 0 0" xyz="0 0 0"/>
          <geometry>
            <cylinder length="0.1" radius="0.3"/>
          </geometry>
        </collision>
        <visual>
          <origin rpy="0 0 0" xyz="0 0 0"/>
          <geometry>
            <cylinder length="0.1" radius="0.3"/>
          </geometry>
        </visual>
      </link>
  </xacro:macro> 
  <!-- Wheels -->
  <xacro:wheels name="right"/>
  <xacro:wheels name="left"/>


  <!-- Wheel joints macro -->
<xacro:macro name="wheel_joints" params="name link x y">
    <joint name="joint_${name}_wheel" type="continuous">
        <parent link="base_link"/>
        <child link="${link}"/>
        <origin xyz= "${x} ${y} 0" rpy="1.5708 0 0"/> <!-- -->
        <axis rpy="0 0 0" xyz="0 0 0.3"/>
    </joint> 
</xacro:macro>
<!-- Wheel joints -->
<xacro:wheel_joints name="left" link="left_wheel" x="-0.3" y="-0.45"/>
<xacro:wheel_joints name="right" link="right_wheel" x="-0.3" y="0.45"/>


<!-- Hokuyo Laser Link -->
<link name="hokuyo">
<collision>
  <origin xyz="0 0 0" rpy="0 0 0"/>
  <geometry>
    <box size="0.01 0.01 0.01"/>
  </geometry>
</collision>
<visual>
  <origin xyz="0 0 0" rpy="0 0 0"/>
  <geometry>
    <mesh filename="package://structure/meshes/hokuyo.dae"/>
  </geometry>
</visual>
<inertial>
  <mass value="0" />
  <origin xyz="0 0 0" rpy="0 0 0"/>
  <inertia ixx="0" ixy="0" ixz="0" iyy="0" iyz="0" izz="0" />
</inertial>
</link> 
<!-- Laser joint -->
<joint name="hokuyo_joint" type="fixed">
  <origin xyz="0 0 0.35" rpy="0 0 0"/>
  <parent link="base_link"/>
  <child link="hokuyo"/>
</joint>


<!-- Lidar stand -->
<link name="stand">
  <visual>
      <origin rpy="0  0  0" xyz="0  0  0"/>
      <geometry>
        <box size="0.1 0.1 0.3"/>
      </geometry>
  </visual>
  <collision>
      <origin rpy="0 0 0" xyz="0 0 0"/>
      <geometry>
        <box size="0.1 0.1 0.3"/>
      </geometry>
  </collision>
  <inertial>
    <mass value="0"/>
    <origin rpy="0 0 0" xyz="0 0 0"/>
    <inertia ixx="0" ixy="0" ixz="0" iyy="0" iyz="0" izz="0"/>
  </inertial>
</link>
<!-- Lidar Stand joint -->
<joint name="stand_joint" type="fixed">
  <origin xyz="0 0 0.2" rpy="0 0 0"/>
  <parent link="base_link"/>
  <child link="stand"/>
</joint>


 <!-- Camera Link -->
  <xacro:property name="camera_link" value="0.05" />
  <link name="camera_link">
    <collision>
      <origin xyz="0 0 0" rpy="0 0 0"/>
      <geometry>
    <box size="${camera_link} ${camera_link} ${camera_link}"/>
      </geometry>
    </collision>
    <visual>
      <origin xyz="0 0 0" rpy="0 0 0"/>
      <geometry>
    <box size="${camera_link} ${camera_link} ${camera_link}"/>
      </geometry>
      <material name="red"/>
    </visual>
    <inertial>
      <mass value="1e-5" />
      <origin xyz="0 0 0" rpy="0 0 0"/>
      <inertia ixx="1e-6" ixy="0" ixz="0" iyy="1e-6" iyz="0" izz="1e-6" />
    </inertial>
  </link> 
<!-- Camera joint -->
<joint name="camera_joint" type="fixed">
    <axis xyz="0 1 0" />
    <origin xyz="0.475 0 0.125" rpy="0 0 0"/>
    <parent link="base_link"/>
    <child link="camera_link"/>
</joint>




</robot>
